Exception in Tkinter callback
Traceback (most recent call last):
  File "C:\Users\Tom\AppData\Local\Programs\Python\Python313\Lib\tkinter\__init__.py", line 2068, in __call__
    return self.func(*args)
           ~~~~~~~~~^^^^^^^
TypeError: Misc.update_idletasks() takes 1 positional argument but 4 were given
Exception in Tkinter callback
Traceback (most recent call last):
  File "C:\Users\Tom\AppData\Local\Programs\Python\Python313\Lib\tkinter\__init__.py", line 2068, in __call__
    return self.func(*args)
           ~~~~~~~~~^^^^^^^
TypeError: Misc.update_idletasks() takes 1 positional argument but 4 were given
Exception in Tkinter callback
Traceback (most recent call last):
  File "C:\Users\Tom\AppData\Local\Programs\Python\Python313\Lib\tkinter\__init__.py", line 2068, in __call__
    return self.func(*args)
           ~~~~~~~~~^^^^^^^
TypeError: Misc.update_idletasks() takes 1 positional argument but 4 were given
Exception in Tkinter callback
Traceback (most recent call last):
  File "C:\Users\Tom\AppData\Local\Programs\Python\Python313\Lib\tkinter\__init__.py", line 2068, in __call__
    return self.func(*args)
           ~~~~~~~~~^^^^^^^
TypeError: Misc.update_idletasks() takes 1 positional argument but 4 were given
Exception in Tkinter callback
Traceback (most recent call last):
  File "C:\Users\Tom\AppData\Local\Programs\Python\Python313\Lib\tkinter\__init__.py", line 2068, in __call__
    return self.func(*args)
           ~~~~~~~~~^^^^^^^
TypeError: Misc.update_idletasks() takes 1 positional argument but 4 were given
Exception in Tkinter callback
Traceback (most recent call last):
  File "C:\Users\Tom\AppData\Local\Programs\Python\Python313\Lib\tkinter\__init__.py", line 2068, in __call__
    return self.func(*args)
           ~~~~~~~~~^^^^^^^
TypeError: Misc.update_idletasks() takes 1 positional argument but 4 were given
Exception in Tkinter callback
Traceback (most recent call last):
  File "C:\Users\Tom\AppData\Local\Programs\Python\Python313\Lib\tkinter\__init__.py", line 2068, in __call__
    return self.func(*args)
           ~~~~~~~~~^^^^^^^
TypeError: Misc.update_idletasks() takes 1 positional argument but 4 were given
Exception in Tkinter callback
Traceback (most recent call last):
  File "C:\Users\Tom\AppData\Local\Programs\Python\Python313\Lib\tkinter\__init__.py", line 2068, in __call__
    return self.func(*args)
           ~~~~~~~~~^^^^^^^
TypeError: Misc.update_idletasks() takes 1 positional argument but 4 were given
Exception in Tkinter callback
Traceback (most recent call last):
  File "C:\Users\Tom\AppData\Local\Programs\Python\Python313\Lib\tkinter\__init__.py", line 2068, in __call__
    return self.func(*args)
           ~~~~~~~~~^^^^^^^
TypeError: Misc.update_idletasks() takes 1 positional argument but 4 were given
Exception in Tkinter callback
Traceback (most recent call last):
  File "C:\Users\Tom\AppData\Local\Programs\Python\Python313\Lib\tkinter\__init__.py", line 2068, in __call__
    return self.func(*args)
           ~~~~~~~~~^^^^^^^
TypeError: Misc.update_idletasks() takes 1 positional argument but 4 were given
Exception in Tkinter callback
Traceback (most recent call last):
  File "C:\Users\Tom\AppData\Local\Programs\Python\Python313\Lib\tkinter\__init__.py", line 2068, in __call__
    return self.func(*args)
           ~~~~~~~~~^^^^^^^
TypeError: Misc.update_idletasks() takes 1 positional argument but 4 were given
Exception in Tkinter callback
Traceback (most recent call last):
  File "C:\Users\Tom\AppData\Local\Programs\Python\Python313\Lib\tkinter\__init__.py", line 2068, in __call__
    return self.func(*args)
           ~~~~~~~~~^^^^^^^
TypeError: Misc.update_idletasks() takes 1 positional argument but 4 were given
Exception in Tkinter callback
Traceback (most recent call last):
  File "C:\Users\Tom\AppData\Local\Programs\Python\Python313\Lib\tkinter\__init__.py", line 2068, in __call__
    return self.func(*args)
           ~~~~~~~~~^^^^^^^
TypeError: Misc.update_idletasks() takes 1 positional argument but 4 were given
Exception in Tkinter callback
Traceback (most recent call last):
  File "C:\Users\Tom\AppData\Local\Programs\Python\Python313\Lib\tkinter\__init__.py", line 2068, in __call__
    return self.func(*args)
           ~~~~~~~~~^^^^^^^
TypeError: Misc.update_idletasks() takes 1 positional argument but 4 were given
Exception in Tkinter callback
Traceback (most recent call last):
  File "C:\Users\Tom\AppData\Local\Programs\Python\Python313\Lib\tkinter\__init__.py", line 2068, in __call__
    return self.func(*args)
           ~~~~~~~~~^^^^^^^
TypeError: Misc.update_idletasks() takes 1 positional argument but 4 were given
Exception in Tkinter callback
Traceback (most recent call last):
  File "C:\Users\Tom\AppData\Local\Programs\Python\Python313\Lib\tkinter\__init__.py", line 2068, in __call__
    return self.func(*args)
           ~~~~~~~~~^^^^^^^
TypeError: Misc.update_idletasks() takes 1 positional argument but 4 were given
Exception in Tkinter callback
Traceback (most recent call last):
  File "C:\Users\Tom\AppData\Local\Programs\Python\Python313\Lib\tkinter\__init__.py", line 2068, in __call__
    return self.func(*args)
           ~~~~~~~~~^^^^^^^
TypeError: Misc.update_idletasks() takes 1 positional argument but 4 were given
Exception in Tkinter callback
Traceback (most recent call last):
  File "C:\Users\Tom\AppData\Local\Programs\Python\Python313\Lib\tkinter\__init__.py", line 2068, in __call__
    return self.func(*args)
           ~~~~~~~~~^^^^^^^
TypeError: Misc.update_idletasks() takes 1 positional argument but 4 were given
Exception in Tkinter callback
Traceback (most recent call last):
  File "C:\Users\Tom\AppData\Local\Programs\Python\Python313\Lib\tkinter\__init__.py", line 2068, in __call__
    return self.func(*args)
           ~~~~~~~~~^^^^^^^
TypeError: Misc.update_idletasks() takes 1 positional argument but 4 were given
Exception in Tkinter callback
Traceback (most recent call last):
  File "C:\Users\Tom\AppData\Local\Programs\Python\Python313\Lib\tkinter\__init__.py", line 2068, in __call__
    return self.func(*args)
           ~~~~~~~~~^^^^^^^
TypeError: Misc.update_idletasks() takes 1 positional argument but 4 were given
Exception in Tkinter callback
Traceback (most recent call last):
  File "C:\Users\Tom\AppData\Local\Programs\Python\Python313\Lib\tkinter\__init__.py", line 2068, in __call__
    return self.func(*args)
           ~~~~~~~~~^^^^^^^
TypeError: Misc.update_idletasks() takes 1 positional argument but 4 were given
Exception in Tkinter callback
Traceback (most recent call last):
  File "C:\Users\Tom\AppData\Local\Programs\Python\Python313\Lib\tkinter\__init__.py", line 2068, in __call__
    return self.func(*args)
           ~~~~~~~~~^^^^^^^
TypeError: Misc.update_idletasks() takes 1 positional argument but 4 were given
Exception in Tkinter callback
Traceback (most recent call last):
  File "C:\Users\Tom\AppData\Local\Programs\Python\Python313\Lib\tkinter\__init__.py", line 2068, in __call__
    return self.func(*args)
           ~~~~~~~~~^^^^^^^
TypeError: Misc.update_idletasks() takes 1 positional argument but 4 were given
Exception in Tkinter callback
Traceback (most recent call last):
  File "C:\Users\Tom\AppData\Local\Programs\Python\Python313\Lib\tkinter\__init__.py", line 2068, in __call__
    return self.func(*args)
           ~~~~~~~~~^^^^^^^
TypeError: Misc.update_idletasks() takes 1 positional argument but 4 were given
Exception in Tkinter callback
Traceback (most recent call last):
  File "C:\Users\Tom\AppData\Local\Programs\Python\Python313\Lib\tkinter\__init__.py", line 2068, in __call__
    return self.func(*args)
           ~~~~~~~~~^^^^^^^
TypeError: Misc.update_idletasks() takes 1 positional argument but 4 were given
Exception in Tkinter callback
Traceback (most recent call last):
  File "C:\Users\Tom\AppData\Local\Programs\Python\Python313\Lib\tkinter\__init__.py", line 2068, in __call__
    return self.func(*args)
           ~~~~~~~~~^^^^^^^
TypeError: Misc.update_idletasks() takes 1 positional argument but 4 were given
Exception in Tkinter callback
Traceback (most recent call last):
  File "C:\Users\Tom\AppData\Local\Programs\Python\Python313\Lib\tkinter\__init__.py", line 2068, in __call__
    return self.func(*args)
           ~~~~~~~~~^^^^^^^
TypeError: Misc.update_idletasks() takes 1 positional argument but 4 were given
Exception in Tkinter callback
Traceback (most recent call last):
  File "C:\Users\Tom\AppData\Local\Programs\Python\Python313\Lib\tkinter\__init__.py", line 2068, in __call__
    return self.func(*args)
           ~~~~~~~~~^^^^^^^
TypeError: Misc.update_idletasks() takes 1 positional argument but 4 were given
Exception in Tkinter callback
Traceback (most recent call last):
  File "C:\Users\Tom\AppData\Local\Programs\Python\Python313\Lib\tkinter\__init__.py", line 2068, in __call__
    return self.func(*args)
           ~~~~~~~~~^^^^^^^
TypeError: Misc.update_idletasks() takes 1 positional argument but 4 were given
Exception in Tkinter callback
Traceback (most recent call last):
  File "C:\Users\Tom\AppData\Local\Programs\Python\Python313\Lib\tkinter\__init__.py", line 2068, in __call__
    return self.func(*args)
           ~~~~~~~~~^^^^^^^
TypeError: Misc.update_idletasks() takes 1 positional argument but 4 were given
Exception in Tkinter callback
Traceback (most recent call last):
  File "C:\Users\Tom\AppData\Local\Programs\Python\Python313\Lib\tkinter\__init__.py", line 2068, in __call__
    return self.func(*args)
           ~~~~~~~~~^^^^^^^
TypeError: Misc.update_idletasks() takes 1 positional argument but 4 were given
Exception in Tkinter callback
Traceback (most recent call last):
  File "C:\Users\Tom\AppData\Local\Programs\Python\Python313\Lib\tkinter\__init__.py", line 2068, in __call__
    return self.func(*args)
           ~~~~~~~~~^^^^^^^
TypeError: Misc.update_idletasks() takes 1 positional argument but 4 were given
Exception in Tkinter callback
Traceback (most recent call last):
  File "C:\Users\Tom\AppData\Local\Programs\Python\Python313\Lib\tkinter\__init__.py", line 2068, in __call__
    return self.func(*args)
           ~~~~~~~~~^^^^^^^
TypeError: Misc.update_idletasks() takes 1 positional argument but 4 were given
Exception in Tkinter callback
Traceback (most recent call last):
  File "C:\Users\Tom\AppData\Local\Programs\Python\Python313\Lib\tkinter\__init__.py", line 2068, in __call__
    return self.func(*args)
           ~~~~~~~~~^^^^^^^
TypeError: Misc.update_idletasks() takes 1 positional argument but 4 were given
